Workbook
Name Slicer_Branch: #N/A
Name Slicer_Branch1: #N/A
Name Slicer_name_of_month: #N/A
Name Slicer_name_of_month1: #N/A
Name Slicer_Position: #N/A
Name Slicer_Position1: #N/A

Sheet PIVOT TABLES
A3: Row Labels | B3: Count of Gender | D3: Row Labels | E3: Count of Gender
A4: Male | B4: 674 | D4: Male | E4: 0.674
A5: Female | B5: 326 | D5: Female | E5: 0.326
A6: Grand Total | B6: 1000 | D6: Grand Total | E6: 1
A9: Row Labels | B9: Count of PayType | D9: Row Labels | E9: Count of PayType
A10: Part Time | B10: 530 | D10: Part Time | E10: 0.53
A11: Full Time | B11: 470 | D11: Full Time | E11: 0.47
A12: Grand Total | B12: 1000 | D12: Grand Total | E12: 1
A15: Row Labels | B15: Count of Department | D15: Row Labels | E15: Count of RATING
A16: Finance | B16: 166 | D16: راتب طبيعي | E16: 500
A17: Maintenance | B17: 132 | D17: راتب عالي | E17: 500
A18: Operations | B18: 111 | D18: Grand Total | E18: 1000
A19: Training | B19: 108
A20: Marketing | B20: 95
A21: Human Resources | B21: 92
A22: Quality Assurance | B22: 91
A23: Administration | B23: 90
A24: Manufacturing | B24: 80
A25: Logistics | B25: 35
A26: Grand Total | B26: 1000
A29: Row Labels | B29: Count of Position
A30: Employee | B30: 671
A31: Manager | B31: 170
A32: Supervisor | B32: 159
A33: Grand Total | B33: 1000
A36: Row Labels | B36: Count of Branch
A37: Sharqia | B37: 213
A38: Giza | B38: 204
A39: Cairo | B39: 203
A40: Ismailia | B40: 192
A41: Alexandria | B41: 188
A42: Grand Total | B42: 1000
A45: Row Labels | B45: Sum of Salary
A46: Finance | B46: 1570859
A47: Maintenance | B47: 1371364
A48: Training | B48: 1009969
A49: Marketing | B49: 953198
A50: Operations | B50: 947425
A51: Quality Assurance | B51: 861686
A52: Administration | B52: 848561
...

Sheet dashboard
E2: ='Pivot Table'!A2 -> Male | F2: ='Pivot Table'!B2 -> 674 | G2: ='Pivot Table'!$F$2 -> 0.674 | I2: ='Pivot Table'!A9 -> Part Time | J2: ='Pivot Table'!B9 -> 530 | K2: ='Pivot Table'!$F$9 -> 0.53 | O2: ='Pivot Table'!H2 -> راتب طبيعي | P2: ='Pivot Table'!I2 -> 500
O3: ='Pivot Table'!H3 -> راتب عالي | P3: ='Pivot Table'!I3 -> 500
E4: ='Pivot Table'!A3 -> Female | F4: ='Pivot Table'!B3 -> 326 | G4: ='Pivot Table'!$F$3 -> 0.326 | I4: ='Pivot Table'!A10 -> Full Time | J4: ='Pivot Table'!B10 -> 470 | K4: ='Pivot Table'!$F$10 -> 0.47

Sheet Pivot Table
A1: Row Labels | B1: Count of Gender | E1: Row Labels | F1: Count of Gender | H1: Row Labels | I1: Count of RATING
A2: Male | B2: 674 | E2: Male | F2: 0.674 | H2: راتب طبيعي | I2: 500
A3: Female | B3: 326 | E3: Female | F3: 0.326 | H3: راتب عالي | I3: 500
A4: Grand Total | B4: 1000 | E4: Grand Total | F4: 1 | H4: Grand Total | I4: 1000
A8: Row Labels | B8: Count of PayType | E8: Row Labels | F8: Count of PayType
A9: Part Time | B9: 530 | E9: Part Time | F9: 0.53
A10: Full Time | B10: 470 | E10: Full Time | F10: 0.47
A11: Grand Total | B11: 1000 | E11: Grand Total | F11: 1
A14: Row Labels | B14: Count of Department | D14: Row Labels | E14: Count of Branch
A15: Finance | B15: 166 | D15: Sharqia | E15: 213
A16: Maintenance | B16: 132 | D16: Giza | E16: 204
A17: Operations | B17: 111 | D17: Cairo | E17: 203
A18: Training | B18: 108 | D18: Ismailia | E18: 192
A19: Marketing | B19: 95 | D19: Alexandria | E19: 188
A20: Human Resources | B20: 92 | D20: Grand Total | E20: 1000
A21: Quality Assurance | B21: 91
A22: Administration | B22: 90
A23: Manufacturing | B23: 80 | D23: Row Labels | E23: Sum of Salary
A24: Logistics | B24: 35 | D24: Giza | E24: 1964781
A25: Grand Total | B25: 1000 | D25: Cairo | E25: 1941358
D26: Alexandria | E26: 1878121
D27: Sharqia | E27: 1797302
A28: Row Labels | B28: Count of Position | D28: Ismailia | E28: 1744676
A29: Employee | B29: 671 | D29: Grand Total | E29: 9326238
A30: Manager | B30: 170
A31: Supervisor | B31: 159
A32: Grand Total | B32: 1000 | D32: Row Labels | E32: Sum of Salary
D33: Finance | E33: 1570859
D34: Maintenance | E34: 1371364
A35: Row Labels | B35: Count of Branch | D35: Training | E35: 1009969
A36: Sharqia | B36: 213 | D36: Marketing | E36: 953198
A37: Giza | B37: 204 | D37: Operations | E37: 947425
A38: Cairo | B38: 203 | D38: Quality Assurance | E38: 861686
A39: Ismailia | B39: 192 | D39: Administration | E39: 848561
A40: Alexandria | B40: 188 | D40: Human Resources | E40: 797470
A41: Grand Total | B41: 1000 | D41: Manufacturing | E41: 654860
D42: Logistics | E42: 310846
D43: Grand Total | E43: 9326238

Sheet data
A1: EmpID | B1: Name | C1: ID No. | D1: Department | E1: Gender | F1: DOB | G1: Age | H1: PayType | I1: Position | J1: Branch | K1: Place of Birth | L1: Hire date | M1: Years no. | N1: Salary | O1: name of month | P1: RATING
A2: 52578 | B2: Emp 1 | C2: 28401260170832 | D2: Maintenance | E2: Male | F2: 30707 | G2: =YEARFRAC(F2,TODAY()) -> 42.280556 | H2: Part Time | I2: Manager | J2: Giza | K2: Cairo | L2: 44724 | M2: =YEARFRAC(L2,TODAY()) -> 3.9027778 | N2: 21194 | O2: =TEXT(L2,"mmm") -> يونيو | P2: =IF(N2>=S$10,"راتب طبيعي","راتب عالي") -> راتب طبيعي
A3: 50880 | B3: Emp 2 | C3: 29211241364134 | D3: Logistics | E3: Male | F3: 33932 | G3: =YEARFRAC(F3,TODAY()) -> 33.452778 | H3: Part Time | I3: Employee | J3: Alexandria | K3: Sharqia | L3: 44725 | M3: =YEARFRAC(L3,TODAY()) -> 3.9 | N3: 5008 | O3: =TEXT(L3,"mmm") -> يونيو | P3: =IF(N3>=S$10,"راتب طبيعي","راتب عالي") -> راتب عالي
A4: 57337 | B4: Emp 3 | C4: 30010092190635 | D4: Manufacturing | E4: Male | F4: 36808 | G4: =YEARFRAC(F4,TODAY()) -> 25.577778 | H4: Part Time | I4: Employee | J4: Ismailia | K4: Giza | L4: 44726 | M4: =YEARFRAC(L4,TODAY()) -> 3.8972222 | N4: 3009 | O4: =TEXT(L4,"mmm") -> يونيو | P4: =IF(N4>=S$10,"راتب طبيعي","راتب عالي") -> راتب عالي | S4: =STDEV(N:N) -> 7188.7378
A5: 55115 | B5: Emp 4 | C5: 29606191791181 | D5: Administration | E5: Female | F5: 35235 | G5: =YEARFRAC(F5,TODAY()) -> 29.883333 | H5: Full Time | I5: Employee | J5: Giza | K5: Monufia | L5: 44727 | M5: =YEARFRAC(L5,TODAY()) -> 3.8944444 | N5: 5313 | O5: =TEXT(L5,"mmm") -> يونيو | P5: =IF(N5>=S$10,"راتب طبيعي","راتب عالي") -> راتب عالي
A6: 59675 | B6: Emp 5 | C6: 29309210163576 | D6: Finance | E6: Male | F6: 34233 | G6: =YEARFRAC(F6,TODAY()) -> 32.627778 | H6: Part Time | I6: Employee | J6: Ismailia | K6: Cairo | L6: 44728 | M6: =YEARFRAC(L6,TODAY()) -> 3.8916667 | N6: 6194 | O6: =TEXT(L6,"mmm") -> يونيو | P6: =IF(N6>=S$10,"راتب طبيعي","راتب عالي") -> راتب طبيعي | S6: =AVERAGE(N:N) -> 9326.238
A7: 52325 | B7: Emp 6 | C7: 28511252167378 | D7: Operations | E7: Male | F7: 31376 | G7: =YEARFRAC(F7,TODAY()) -> 40.45 | H7: Full Time | I7: Employee | J7: Alexandria | K7: Giza | L7: 44729 | M7: =YEARFRAC(L7,TODAY()) -> 3.8888889 | N7: 4027 | O7: =TEXT(L7,"mmm") -> يونيو | P7: =IF(N7>=S$10,"راتب طبيعي","راتب عالي") -> راتب عالي | S7: نسبة تفاوت
A8: 57592 | B8: Emp 7 | C8: 28308071379248 | D8: Maintenance | E8: Female | F8: 30535 | G8: =YEARFRAC(F8,TODAY()) -> 42.75 | H8: Part Time | I8: Supervisor | J8: Ismailia | K8: Sharqia | L8: 44730 | M8: =YEARFRAC(L8,TODAY()) -> 3.8861111 | N8: 12074 | O8: =TEXT(L8,"mmm") -> يونيو | P8: =IF(N8>=S$10,"راتب طبيعي","راتب عالي") -> راتب طبيعي | S8: =S4/S6 -> 0.77080788
A9: 55955 | B9: Emp 8 | C9: 28903060171174 | D9: Manufacturing | E9: Male | F9: 32573 | G9: =YEARFRAC(F9,TODAY()) -> 37.169444 | H9: Full Time | I9: Supervisor | J9: Cairo | K9: Cairo | L9: 44731 | M9: =YEARFRAC(L9,TODAY()) -> 3.8833333 | N9: 10027 | O9: =TEXT(L9,"mmm") -> يونيو | P9: =IF(N9>=S$10,"راتب طبيعي","راتب عالي") -> راتب طبيعي
A10: 50042 | B10: Emp 9 | C10: 28808120183762 | D10: Maintenance | E10: Female | F10: 32367 | G10: =YEARFRAC(F10,TODAY()) -> 37.736111 | H10: Full Time | I10: Employee | J10: Alexandria | K10: Cairo | L10: 44732 | M10: =YEARFRAC(L10,TODAY()) -> 3.8805556 | N10: 6858 | O10: =TEXT(L10,"mmm") -> يونيو | P10: =IF(N10>=S$10,"راتب طبيعي","راتب عالي") -> راتب طبيعي | S10: =MEDIAN(N:N) -> 5959.5
A11: 57941 | B11: Emp 10 | C11: 30303060168572 | D11: Quality Assurance | E11: Male | F11: 37686 | G11: =YEARFRAC(F11,TODAY()) -> 23.169444 | H11: Full Time | I11: Employee | J11: Cairo | K11: Cairo | L11: 44733 | M11: =YEARFRAC(L11,TODAY()) -> 3.8777778 | N11: 4444 | O11: =TEXT(L11,"mmm") -> يونيو | P11: =IF(N11>=S$10,"راتب طبيعي","راتب عالي") -> راتب عالي
A12: 54639 | B12: Emp 11 | C12: 28202240173227 | D12: Quality Assurance | E12: Female | F12: 30006 | G12: =YEARFRAC(F12,TODAY()) -> 44.202778 | H12: Full Time | I12: Manager | J12: Alexandria | K12: Cairo | L12: 44734 | M12: =YEARFRAC(L12,TODAY()) -> 3.875 | N12: 29222 | O12: =TEXT(L12,"mmm") -> يونيو | P12: =IF(N12>=S$10,"راتب طبيعي","راتب عالي") -> راتب طبيعي
A13: 55504 | B13: Emp 12 | C13: 30305030155122 | D13: Manufacturing | E13: Female | F13: 37744 | G13: =YEARFRAC(F13,TODAY()) -> 23.011111 | H13: Part Time | I13: Supervisor | J13: Ismailia | K13: Cairo | L13: 44735 | M13: =YEARFRAC(L13,TODAY()) -> 3.8722222 | N13: 12169 | O13: =TEXT(L13,"mmm") -> يونيو | P13: =IF(N13>=S$10,"راتب طبيعي","راتب عالي") -> راتب طبيعي
A14: 52518 | B14: Emp 13 | C14: 28612070158122 | D14: Maintenance | E14: Female | F14: 31753 | G14: =YEARFRAC(F14,TODAY()) -> 39.416667 | H14: Part Time | I14: Supervisor | J14: Giza | K14: Cairo | L14: 44736 | M14: =YEARFRAC(L14,TODAY()) -> 3.8694444 | N14: 14015 | O14: =TEXT(L14,"mmm") -> يونيو | P14: =IF(N14>=S$10,"راتب طبيعي","راتب عالي") -> راتب طبيعي
A15: 54193 | B15: Emp 14 | C15: 29303120161011 | D15: Maintenance | E15: Male | F15: 34040 | G15: =YEARFRAC(F15,TODAY()) -> 33.152778 | H15: Full Time | I15: Employee | J15: Cairo | K15: Cairo | L15: 44737 | M15: =YEARFRAC(L15,TODAY()) -> 3.8666667 | N15: 5951 | O15: =TEXT(L15,"mmm") -> يونيو | P15: =IF(N15>=S$10,"راتب طبيعي","راتب عالي") -> راتب عالي
A16: 50028 | B16: Emp 15 | C16: 29211090169729 | D16: Maintenance | E16: Female | F16: 33917 | G16: =YEARFRAC(F16,TODAY()) -> 33.494444 | H16: Part Time | I16: Employee | J16: Alexandria | K16: Cairo | L16: 44738 | M16: =YEARFRAC(L16,TODAY()) -> 3.8638889 | N16: 3673 | O16: =TEXT(L16,"mmm") -> يونيو | P16: =IF(N16>=S$10,"راتب طبيعي","راتب عالي") -> راتب عالي
A17: 53437 | B17: Emp 16 | C17: 29203190155848 | D17: Marketing | E17: Female | F17: 33682 | G17: =YEARFRAC(F17,TODAY()) -> 34.133333 | H17: Part Time | I17: Employee | J17: Giza | K17: Cairo | L17: 44739 | M17: =YEARFRAC(L17,TODAY()) -> 3.8611111 | N17: 4265 | O17: =TEXT(L17,"mmm") -> يونيو | P17: =IF(N17>=S$10,"راتب طبيعي","راتب عالي") -> راتب عالي
A18: 59081 | B18: Emp 17 | C18: 30111090181931 | D18: Finance | E18: Male | F18: 37204 | G18: =YEARFRAC(F18,TODAY()) -> 24.494444 | H18: Part Time | I18: Manager | J18: Giza | K18: Cairo | L18: 44740 | M18: =YEARFRAC(L18,TODAY()) -> 3.8583333 | N18: 24474 | O18: =TEXT(L18,"mmm") -> يونيو | P18: =IF(N18>=S$10,"راتب طبيعي","راتب عالي") -> راتب طبيعي
A19: 50162 | B19: Emp 18 | C19: 28907160185937 | D19: Maintenance | E19: Male | F19: 32705 | G19: =YEARFRAC(F19,TODAY()) -> 36.808333 | H19: Full Time | I19: Employee | J19: Sharqia | K19: Cairo | L19: 44741 | M19: =YEARFRAC(L19,TODAY()) -> 3.8555556 | N19: 4561 | O19: =TEXT(L19,"mmm") -> يونيو | P19: =IF(N19>=S$10,"راتب طبيعي","راتب عالي") -> راتب عالي
A20: 52806 | B20: Emp 19 | C20: 28601240154257 | D20: Operations | E20: Male | F20: 31436 | G20: =YEARFRAC(F20,TODAY()) -> 40.286111 | H20: Part Time | I20: Manager | J20: Giza | K20: Cairo | L20: 44742 | M20: =YEARFRAC(L20,TODAY()) -> 3.8527778 | N20: 22799 | O20: =TEXT(L20,"mmm") -> يونيو | P20: =IF(N20>=S$10,"راتب طبيعي","راتب عالي") -> راتب طبيعي
A21: 58595 | B21: Emp 20 | C21: 29205240170277 | D21: Marketing | E21: Male | F21: 33748 | G21: =YEARFRAC(F21,TODAY()) -> 33.952778 | H21: Part Time | I21: Supervisor | J21: Ismailia | K21: Cairo | L21: 44743 | M21: =YEARFRAC(L21,TODAY()) -> 3.85 | N21: 11896 | O21: =TEXT(L21,"mmm") -> يوليو | P21: =IF(N21>=S$10,"راتب طبيعي","راتب عالي") -> راتب طبيعي
A22: 50801 | B22: Emp 21 | C22: 30301070171536 | D22: Quality Assurance | E22: Male | F22: 37628 | G22: =YEARFRAC(F22,TODAY()) -> 23.333333 | H22: Part Time | I22: Employee | J22: Sharqia | K22: Cairo | L22: 44744 | M22: =YEARFRAC(L22,TODAY()) -> 3.8472222 | N22: 3906 | O22: =TEXT(L22,"mmm") -> يوليو | P22: =IF(N22>=S$10,"راتب طبيعي","راتب عالي") -> راتب عالي
... A1001: 50846 | B1001: Emp 1000 | C1001: 29602231790654 | D1001: Operations | E1001: Male | F1001: 35118 | G1001: =YEARFRAC(F1001,TODAY()) -> 30.205556 | H1001: Part Time | I1001: Supervisor | J1001: Cairo | K1001: Monufia | L1001: 45723 | M1001: =YEARFRAC(L1001,TODAY()) -> 1.1666667 | N1001: 7000 | O1001: =TEXT(L1001,"mmm") -> مارس | P1001: =IF(N1001>=S$10,"راتب طبيعي","راتب عالي") -> راتب طبيعي
